<?xml version="1.0" ?>
<!-- =================================================================================== -->
<!-- |    This document was autogenerated by xacro from simpledog.urdf.xacro           | -->
<!-- |    EDITING THIS FILE BY HAND IS NOT RECOMMENDED                                 | -->
<!-- =================================================================================== -->
<!-- This URDF was automatically created by SolidWorks to URDF Exporter! Originally created by Stephen Brawner (brawner@gmail.com)
     Commit Version: 1.5.0-0-g9aa0fdb  Build Version: 1.5.7004.21443
     For more information, please see http://wiki.ros.org/sw_urdf_exporter -->
<robot name="quadruped_model" xmlns:xacro="http://ros.org/wiki/xacro">
  <joint name="velodyne_base_mount_joint" type="fixed">
    <origin rpy="0 0 0" xyz="0.26  0  0.118"/>
    <parent link="base"/>
    <child link="velodyne_base_link"/>
  </joint>
  <link name="velodyne_base_link">
    <inertial>
      <mass value="0.83"/>
      <origin xyz="0 0 0.03585"/>
      <inertia ixx="0.000908059425" ixy="0" ixz="0" iyy="0.000908059425" iyz="0" izz="0.0011049624"/>
    </inertial>
    <visual>
      <geometry>
        <mesh filename="package://velodyne_description/meshes/VLP16_base_1.dae"/>
      </geometry>
    </visual>
    <visual>
      <geometry>
        <mesh filename="package://velodyne_description/meshes/VLP16_base_2.dae"/>
      </geometry>
    </visual>
    <collision>
      <origin rpy="0 0 0" xyz="0 0 0.03585"/>
      <geometry>
        <cylinder length="0.0717" radius="0.0516"/>
      </geometry>
    </collision>
  </link>
  <joint name="velodyne_base_scan_joint" type="fixed">
    <origin rpy="0 0 0" xyz="0 0 0.0377"/>
    <parent link="velodyne_base_link"/>
    <child link="velodyne"/>
  </joint>
  <link name="velodyne">
    <inertial>
      <mass value="0.01"/>
      <origin xyz="0 0 0"/>
      <inertia ixx="1e-7" ixy="0" ixz="0" iyy="1e-7" iyz="0" izz="1e-7"/>
    </inertial>
    <visual>
      <origin xyz="0 0 -0.0377"/>
      <geometry>
        <mesh filename="package://velodyne_description/meshes/VLP16_scan.dae"/>
      </geometry>
    </visual>
  </link>
  <!-- Gazebo requires the velodyne_gazebo_plugins package -->
  <gazebo reference="velodyne">
    <sensor name="velodyne-VLP16" type="ray">
      <pose>0 0 0 0 0 0</pose>
      <visualize>false</visualize>
      <update_rate>10</update_rate>
      <ray>
        <scan>
          <horizontal>
            <samples>360</samples>
            <resolution>1</resolution>
            <min_angle>-3.14159265359</min_angle>
            <max_angle>3.14159265359</max_angle>
          </horizontal>
          <vertical>
            <samples>16</samples>
            <resolution>1</resolution>
            <min_angle>-0.261799387799</min_angle>
            <max_angle> 0.261799387799</max_angle>
          </vertical>
        </scan>
        <range>
          <min>0.3</min>
          <max>131.0</max>
          <resolution>0.001</resolution>
        </range>
        <noise>
          <type>gaussian</type>
          <mean>0.0</mean>
          <stddev>0.0</stddev>
        </noise>
      </ray>
      <plugin filename="libgazebo_ros_velodyne_laser.so" name="gazebo_ros_laser_controller">
        <topicName>/velodyne_points</topicName>
        <frameName>velodyne</frameName>
        <min_range>0.9</min_range>
        <max_range>130.0</max_range>
        <gaussianNoise>0.008</gaussianNoise>
      </plugin>
    </sensor>
  </gazebo>
  <!--  <xacro:include filename="$(find simpledog)/urdf/rplidar.xacro" />
        <xacro:property name="rplidar_offset_x" value="0" />
        <xacro:property name="rplidar_offset_y" value="0" />
        <xacro:property name="rplidar_offset_z" value="0.12" />
        <joint name="rplidar_joint" type="fixed">
        <origin xyz="${rplidar_offset_x} ${rplidar_offset_y} ${rplidar_offset_z}" rpy="0 0 0" />
        <parent link="base_link"/>
        <child link="laser_link"/>
        </joint>

        <xacro:rplidar prefix="laser"/>    -->
  <link name="imu_link">
    <inertial>
      <mass value="0.1"/>
      <origin rpy="0 0 0" xyz="0 0 0"/>
      <inertia ixx="0.0001" ixy="0" ixz="0" iyy="0.000001" iyz="0" izz="0.0001"/>
    </inertial>
    <visual>
      <origin rpy="0 0 0" xyz="0 0 0"/>
      <geometry>
        <box size="0.06 0.06 0.02"/>
      </geometry>
    </visual>
    <collision>
      <origin rpy="0 0 0" xyz="0 0 0"/>
      <geometry>
        <box size="0.06 0.06 0.02"/>
      </geometry>
    </collision>
  </link>
  <joint name="imu_joint" type="fixed">
    <axis xyz="0 0 0"/>
    <!--0 1 0 -->
    <origin rpy="0 0 0" xyz="0.13 0 0.12"/>
    <parent link="base"/>
    <child link="imu_link"/>
  </joint>
  <gazebo reference="base_link">
    <mu1 value="10.0"/>
    <mu2 value="10.0"/>
    <kp value="10000000.0"/>
    <kd value="1.0"/>
    <fdir1 value="1 0 0"/>
    <gravity value="ture"/>
  </gazebo>
  <!--load the gazebo rosz-control plug in-->
  <gazebo>
    <plugin filename="librobot_state_gazebo_ros_control_plugin.so" name="balance_controller">
      <robotNamespace>/simpledog</robotNamespace>
      <robotSimType>balance_controller/SimRobotStateHardwareInterface</robotSimType>
    </plugin>
  </gazebo>
  <gazebo reference="imu_link">
    <gravity>true</gravity>
    <sensor name="imu" type="imu">
      `
      
      <always_on>true</always_on>
      <update_rate>200</update_rate>
      <visualize>true</visualize>
      <topic>__default_topic__</topic>
      <plugin filename="libgazebo_ros_imu_sensor.so" name="imu_plugin">
        <topicName>imu</topicName>
        <bodyName>imu_link</bodyName>
        <updateRateHZ>200.0</updateRateHZ>
        <gaussianNoise>1e-06</gaussianNoise>
        <xyzOffset>0 0 0</xyzOffset>
        <rpyOffset>0 0 0</rpyOffset>
        <frameName>imu_link</frameName>
      </plugin>
      <pose>0 0 0 0 0 0</pose>
    </sensor>
    <material>Gazebo/Blue</material>
  </gazebo>
  <!-- <gazebo reference="imu_link">
    <gravity>true</gravity>
    <sensor name="imu" type="imu">`
      <always_on>true</always_on>
      <update_rate>400</update_rate>
      <visualize>true</visualize>
      <topic>__default_topic__</topic>
      <plugin filename="libgazebo_ros_imu_sensor.so" name="imu_plugin">
        <topicName>imu</topicName>
        <bodyName>imu_link</bodyName>
        <updateRateHZ>10.0</updateRateHZ>
        <gaussianNoise>1e-06</gaussianNoise>
        <xyzOffset>0 0 0</xyzOffset>
        <rpyOffset>0 0 0</rpyOffset>
        <frameName>imu_link</frameName>
      </plugin>
      <pose>0 0 0 0 0 0</pose>
    </sensor>
    <material>Gazebo/Blue</material>
  </gazebo> -->
  <!-- <gazebo reference="imu_link">
    <sensor type="imu" name="imu">
      <always_on>true</always_on>
      <visualize>$(arg imu_visual)</visualize>
    </sensor>
    <material>Gazebo/Grey</material>
  </gazebo>

  <gazebo>
    <plugin name="imu_plugin" filename="libgazebo_ros_imu.so">
      <alwaysOn>true</alwaysOn>
      <bodyName>imu_link</bodyName>
      <frameName>imu_link</frameName>
      <topicName>imu</topicName>
      <serviceName>imu_service</serviceName>
      <gaussianNoise>0.0</gaussianNoise>
      <updateRate>200</updateRate>
      <imu>
        <noise>
          <type>gaussian</type>
          <rate>
            <mean>0.0</mean>
            <stddev>2e-4</stddev>
            <bias_mean>0.0000075</bias_mean>
            <bias_stddev>0.0000008</bias_stddev>
          </rate>
          <accel>
            <mean>0.0</mean>
            <stddev>1.7e-2</stddev>
            <bias_mean>0.1</bias_mean>
            <bias_stddev>0.001</bias_stddev>
          </accel>
        </noise>
      </imu>
    </plugin>
  </gazebo>

  <gazebo reference="base_scan">
    <material>Gazebo/FlatBlack</material>
    <sensor type="ray" name="lds_lfcd_sensor">
      <pose>0 0 0 0 0 0</pose>
      <visualize>$(arg laser_visual)</visualize>
      <update_rate>5</update_rate>
      <ray>
        <scan>
          <horizontal>
            <samples>360</samples>
            <resolution>1</resolution>
            <min_angle>0.0</min_angle>
            <max_angle>6.28319</max_angle>
          </horizontal>
        </scan>
        <range>
          <min>0.120</min>
          <max>3.5</max>
          <resolution>0.015</resolution>
        </range>
        <noise>
          <type>gaussian</type>
          <mean>0.0</mean>
          <stddev>0.01</stddev>
        </noise>
      </ray>
      <plugin name="gazebo_ros_lds_lfcd_controller" filename="libgazebo_ros_laser.so">
        <topicName>scan</topicName>
        <frameName>base_scan</frameName>
      </plugin>
    </sensor>
  </gazebo>

  <gazebo reference="camera_rgb_frame">
    <sensor type="depth" name="realsense_R200">
      <always_on>true</always_on>
      <visualize>$(arg camera_visual)</visualize>
      <camera>
          <horizontal_fov>1.3439</horizontal_fov>
          <image>
              <width>1920</width>
              <height>1080</height>
              <format>R8G8B8</format>
          </image>
          <depth_camera></depth_camera>
          <clip>
              <near>0.03</near>
              <far>100</far>
          </clip>
      </camera>
      <plugin name="camera_controller" filename="libgazebo_ros_openni_kinect.so">
        <baseline>0.2</baseline>
        <alwaysOn>true</alwaysOn>
        <updateRate>30.0</updateRate>
        <cameraName>camera</cameraName>
        <frameName>camera_rgb_optical_frame</frameName>
        <imageTopicName>rgb/image_raw</imageTopicName>
        <depthImageTopicName>depth/image_raw</depthImageTopicName>
        <pointCloudTopicName>depth/points</pointCloudTopicName>
        <cameraInfoTopicName>rgb/camera_info</cameraInfoTopicName>
        <depthImageCameraInfoTopicName>depth/camera_info</depthImageCameraInfoTopicName>
        <pointCloudCutoff>0.4</pointCloudCutoff>
            <hackBaseline>0.07</hackBaseline>
            <distortionK1>0.0</distortionK1>
            <distortionK2>0.0</distortionK2>
            <distortionK3>0.0</distortionK3>
            <distortionT1>0.0</distortionT1>
            <distortionT2>0.0</distortionT2>
        <CxPrime>0.0</CxPrime>
        <Cx>0.0</Cx>
        <Cy>0.0</Cy>
        <focalLength>0</focalLength>
        <hackBaseline>0</hackBaseline>
      </plugin>
    </sensor>
  </gazebo>-->
  <!-- Create kinect reference frame -->
  <!-- Add mesh for kinect -->
  <link name="camera_link">
    <origin rpy="0 0 0" xyz="0 0 0"/>
    <mass value="1.238"/>
    <visual>
      <origin rpy="0 0 1.5708" xyz="0 0 0"/>
      <geometry>
        <mesh filename="package://simpledog/meshes/kinect.dae"/>
      </geometry>
    </visual>
    <collision>
      <geometry>
        <box size="0.07 0.3 0.09"/>
      </geometry>
    </collision>
  </link>
  <joint name="camera_optical_joint" type="fixed">
    <origin rpy="-1.5708 0 -1.5708" xyz="0 0 0"/>
    <parent link="camera_link"/>
    <child link="camera_frame_optical"/>
  </joint>
  <link name="camera_frame_optical"/>
  <gazebo reference="camera_link">
    <sensor name="camera" type="depth">
      <always_on>true</always_on>
      <update_rate>10.0</update_rate>
      <camera>
        <horizontal_fov>1.04666666667</horizontal_fov>
        <image>
          <format>R8G8B8</format>
          <width>640</width>
          <height>480</height>
        </image>
        <clip>
          <near>0.05</near>
          <far>8.0</far>
        </clip>
      </camera>
      <plugin filename="libgazebo_ros_openni_kinect.so" name="kinect_camera_controller">
        <cameraName>camera</cameraName>
        <alwaysOn>true</alwaysOn>
        <updateRate>10.0</updateRate>
        <!-- <imageTopicName>rgb/image_raw</imageTopicName> -->
        <!-- <depthImageTopicName>depth/image_raw</depthImageTopicName> -->
        <pointCloudTopicName>depth/points</pointCloudTopicName>
        <cameraInfoTopicName>camera_info</cameraInfoTopicName>
        <depthImageCameraInfoTopicName>depth/camera_info</depthImageCameraInfoTopicName>
        <frameName>camera_frame_optical</frameName>
        <baseline>0.1</baseline>
        <distortion_k1>0.0</distortion_k1>
        <distortion_k2>0.0</distortion_k2>
        <distortion_k3>0.0</distortion_k3>
        <distortion_t1>0.0</distortion_t1>
        <distortion_t2>0.0</distortion_t2>
        <pointCloudCutoff>0.4</pointCloudCutoff>
        <!--<robotNamespace>${robot_namespace}</robotNamespace>-->
      </plugin>
    </sensor>
  </gazebo>
  <joint name="kinect_frame_joint" type="fixed">
    <origin rpy="0 0 0" xyz="0.5 0.0 0.0"/>
    <parent link="base"/>
    <child link="camera_link"/>
  </joint>
  <gazebo reference="LF_HAAjoint">
    <provideFeedback>true</provideFeedback>
  </gazebo>
  <transmission name="LF_HAAjoint_trans" type="SimpleTransmission">
    <type>transmission_interface/SimpleTransmission</type>
    <actuator name="LF_HAAjoint_motor">
      <mechanicalReduction>1</mechanicalReduction>
    </actuator>
    <joint name="LF_HAAjoint">
      <hardwareInterface>hardware_interface/EffortJointInterface</hardwareInterface>
      <hardwareInterface>hardware_interface/PositionJointInterface</hardwareInterface>
      <hardwareInterface>hardware_interface/VelocityJointInterface</hardwareInterface>
    </joint>
  </transmission>
  <gazebo reference="LF_HFEjoint">
    <provideFeedback>true</provideFeedback>
  </gazebo>
  <transmission name="LF_HFEjoint_trans" type="SimpleTransmission">
    <type>transmission_interface/SimpleTransmission</type>
    <actuator name="LF_HFEjoint_motor">
      <mechanicalReduction>1</mechanicalReduction>
    </actuator>
    <joint name="LF_HFEjoint">
      <hardwareInterface>hardware_interface/EffortJointInterface</hardwareInterface>
      <hardwareInterface>hardware_interface/PositionJointInterface</hardwareInterface>
      <hardwareInterface>hardware_interface/VelocityJointInterface</hardwareInterface>
    </joint>
  </transmission>
  <gazebo reference="LF_KFEjoint">
    <provideFeedback>true</provideFeedback>
  </gazebo>
  <transmission name="LF_KFEjoint_trans" type="SimpleTransmission">
    <type>transmission_interface/SimpleTransmission</type>
    <actuator name="LF_KFEjoint_motor">
      <mechanicalReduction>1</mechanicalReduction>
    </actuator>
    <joint name="LF_KFEjoint">
      <hardwareInterface>hardware_interface/EffortJointInterface</hardwareInterface>
      <hardwareInterface>hardware_interface/PositionJointInterface</hardwareInterface>
      <hardwareInterface>hardware_interface/VelocityJointInterface</hardwareInterface>
    </joint>
  </transmission>
  <gazebo reference="RF_HAAjoint">
    <provideFeedback>true</provideFeedback>
  </gazebo>
  <transmission name="RF_HAAjoint_trans" type="SimpleTransmission">
    <type>transmission_interface/SimpleTransmission</type>
    <actuator name="RF_HAAjoint_motor">
      <mechanicalReduction>1</mechanicalReduction>
    </actuator>
    <joint name="RF_HAAjoint">
      <hardwareInterface>hardware_interface/EffortJointInterface</hardwareInterface>
      <hardwareInterface>hardware_interface/PositionJointInterface</hardwareInterface>
      <hardwareInterface>hardware_interface/VelocityJointInterface</hardwareInterface>
    </joint>
  </transmission>
  <gazebo reference="RF_HFEjoint">
    <provideFeedback>true</provideFeedback>
  </gazebo>
  <transmission name="RF_HFEjoint_trans" type="SimpleTransmission">
    <type>transmission_interface/SimpleTransmission</type>
    <actuator name="RF_HFEjoint_motor">
      <mechanicalReduction>1</mechanicalReduction>
    </actuator>
    <joint name="RF_HFEjoint">
      <hardwareInterface>hardware_interface/EffortJointInterface</hardwareInterface>
      <hardwareInterface>hardware_interface/PositionJointInterface</hardwareInterface>
      <hardwareInterface>hardware_interface/VelocityJointInterface</hardwareInterface>
    </joint>
  </transmission>
  <gazebo reference="RF_KFEjoint">
    <provideFeedback>true</provideFeedback>
  </gazebo>
  <transmission name="RF_KFEjoint_trans" type="SimpleTransmission">
    <type>transmission_interface/SimpleTransmission</type>
    <actuator name="RF_KFEjoint_motor">
      <mechanicalReduction>1</mechanicalReduction>
    </actuator>
    <joint name="RF_KFEjoint">
      <hardwareInterface>hardware_interface/EffortJointInterface</hardwareInterface>
      <hardwareInterface>hardware_interface/PositionJointInterface</hardwareInterface>
      <hardwareInterface>hardware_interface/VelocityJointInterface</hardwareInterface>
    </joint>
  </transmission>
  <gazebo reference="RH_HAAjoint">
    <provideFeedback>true</provideFeedback>
  </gazebo>
  <transmission name="RH_HAAjoint_trans" type="SimpleTransmission">
    <type>transmission_interface/SimpleTransmission</type>
    <actuator name="RH_HAAjoint_motor">
      <mechanicalReduction>1</mechanicalReduction>
    </actuator>
    <joint name="RH_HAAjoint">
      <hardwareInterface>hardware_interface/EffortJointInterface</hardwareInterface>
      <hardwareInterface>hardware_interface/PositionJointInterface</hardwareInterface>
      <hardwareInterface>hardware_interface/VelocityJointInterface</hardwareInterface>
    </joint>
  </transmission>
  <gazebo reference="RH_HFEjoint">
    <provideFeedback>true</provideFeedback>
  </gazebo>
  <transmission name="RH_HFEjoint_trans" type="SimpleTransmission">
    <type>transmission_interface/SimpleTransmission</type>
    <actuator name="RH_HFEjoint_motor">
      <mechanicalReduction>1</mechanicalReduction>
    </actuator>
    <joint name="RH_HFEjoint">
      <hardwareInterface>hardware_interface/EffortJointInterface</hardwareInterface>
      <hardwareInterface>hardware_interface/PositionJointInterface</hardwareInterface>
      <hardwareInterface>hardware_interface/VelocityJointInterface</hardwareInterface>
    </joint>
  </transmission>
  <gazebo reference="RH_KFEjoint">
    <provideFeedback>true</provideFeedback>
  </gazebo>
  <transmission name="RH_KFEjoint_trans" type="SimpleTransmission">
    <type>transmission_interface/SimpleTransmission</type>
    <actuator name="RH_KFEjoint_motor">
      <mechanicalReduction>1</mechanicalReduction>
    </actuator>
    <joint name="RH_KFEjoint">
      <hardwareInterface>hardware_interface/EffortJointInterface</hardwareInterface>
      <hardwareInterface>hardware_interface/PositionJointInterface</hardwareInterface>
      <hardwareInterface>hardware_interface/VelocityJointInterface</hardwareInterface>
    </joint>
  </transmission>
  <gazebo reference="LH_HAAjoint">
    <provideFeedback>true</provideFeedback>
  </gazebo>
  <transmission name="LH_HAAjoint_trans" type="SimpleTransmission">
    <type>transmission_interface/SimpleTransmission</type>
    <actuator name="LH_HAAjoint_motor">
      <mechanicalReduction>1</mechanicalReduction>
    </actuator>
    <joint name="LH_HAAjoint">
      <hardwareInterface>hardware_interface/EffortJointInterface</hardwareInterface>
      <hardwareInterface>hardware_interface/PositionJointInterface</hardwareInterface>
      <hardwareInterface>hardware_interface/VelocityJointInterface</hardwareInterface>
    </joint>
  </transmission>
  <gazebo reference="LH_HFEjoint">
    <provideFeedback>true</provideFeedback>
  </gazebo>
  <transmission name="LH_HFEjoint_trans" type="SimpleTransmission">
    <type>transmission_interface/SimpleTransmission</type>
    <actuator name="LH_HFEjoint_motor">
      <mechanicalReduction>1</mechanicalReduction>
    </actuator>
    <joint name="LH_HFEjoint">
      <hardwareInterface>hardware_interface/EffortJointInterface</hardwareInterface>
      <hardwareInterface>hardware_interface/PositionJointInterface</hardwareInterface>
      <hardwareInterface>hardware_interface/VelocityJointInterface</hardwareInterface>
    </joint>
  </transmission>
  <gazebo reference="LH_KFEjoint">
    <provideFeedback>true</provideFeedback>
  </gazebo>
  <transmission name="LH_KFEjoint_trans" type="SimpleTransmission">
    <type>transmission_interface/SimpleTransmission</type>
    <actuator name="LH_KFEjoint_motor">
      <mechanicalReduction>1</mechanicalReduction>
    </actuator>
    <joint name="LH_KFEjoint">
      <hardwareInterface>hardware_interface/EffortJointInterface</hardwareInterface>
      <hardwareInterface>hardware_interface/PositionJointInterface</hardwareInterface>
      <hardwareInterface>hardware_interface/VelocityJointInterface</hardwareInterface>
    </joint>
  </transmission>
  <gazebo reference="LF_FOOT_Link">
    <material>Gazebo/DarkGrey</material>
    <mu1 value="1000.0"/>
    <mu2 value="1000.0"/>
    <kp value="1000.0"/>
    <kd value="100.0"/>
    <fdir1 value="0 0 0"/>
    <minDepth value="0"/>
    <maxVel value="0"/>
  </gazebo>
  <gazebo reference="LF_FOOT_joint">
    <provideFeedback value="true"/>
  </gazebo>
  <gazebo reference="LF_FOOT_Link">
    <turnGravityOff>true</turnGravityOff>
    <selfCollide>false</selfCollide>
    <maxContacts>1</maxContacts>
    <sensor name="LF_FOOT_contact_sensor" type="contact">
      <update_rate>1000.0</update_rate>
      <contact>
        <collision>LF_ADAPTERLink_fixed_joint_lump__LF_FOOT_Link_collision_1</collision>
      </contact>
      <plugin filename="libgazebo_ros_bumper.so" name="LF_FOOT_gazebo_ros_bumper_controller">
        <alwaysOn>true</alwaysOn>
        <frameName>LF_FOOT_Link</frameName>
        <!-- <frameName>world</frameName> -->
        <updateRate>1000.0</updateRate>
        <bumperTopicName>LF_FOOT_bumper</bumperTopicName>
      </plugin>
    </sensor>
  </gazebo>
  <!-- <gazebo>
                <plugin name="ft_sensor" filename="libgazebo_ros_ft_sensor.so">
                    <updateRate>100.0</updateRate>
                    <topicName>${foot_prefix}_joint_ft_feedback</topicName>
                    <jointName>${foot_prefix}_joint</jointName>
                </plugin>
            </gazebo> -->
  <!-- <gazebo>
              <plugin name="f3d_${foot_prefix}_controller" filename="libgazebo_ros_f3d.so">
                <alwaysOn>true</alwaysOn>
                <updateRate>10.0</updateRate>
                <frameName>base_link</frameName>
                <bodyName>${foot_prefix}_Link</bodyName>
                <topicName>${foot_prefix}_force_ground_truth</topicName>
              </plugin>
            </gazebo> -->
  <gazebo reference="RF_FOOT_Link">
    <material>Gazebo/DarkGrey</material>
    <mu1 value="1000.0"/>
    <mu2 value="1000.0"/>
    <kp value="1000.0"/>
    <kd value="100.0"/>
    <fdir1 value="0 0 0"/>
    <minDepth value="0"/>
    <maxVel value="0"/>
  </gazebo>
  <gazebo reference="RF_FOOT_joint">
    <provideFeedback value="true"/>
  </gazebo>
  <gazebo reference="RF_FOOT_Link">
    <turnGravityOff>true</turnGravityOff>
    <selfCollide>false</selfCollide>
    <maxContacts>1</maxContacts>
    <sensor name="RF_FOOT_contact_sensor" type="contact">
      <update_rate>1000.0</update_rate>
      <contact>
        <collision>RF_ADAPTERLink_fixed_joint_lump__RF_FOOT_Link_collision_1</collision>
      </contact>
      <plugin filename="libgazebo_ros_bumper.so" name="RF_FOOT_gazebo_ros_bumper_controller">
        <alwaysOn>true</alwaysOn>
        <frameName>RF_FOOT_Link</frameName>
        <!-- <frameName>world</frameName> -->
        <updateRate>1000.0</updateRate>
        <bumperTopicName>RF_FOOT_bumper</bumperTopicName>
      </plugin>
    </sensor>
  </gazebo>
  <!-- <gazebo>
                <plugin name="ft_sensor" filename="libgazebo_ros_ft_sensor.so">
                    <updateRate>100.0</updateRate>
                    <topicName>${foot_prefix}_joint_ft_feedback</topicName>
                    <jointName>${foot_prefix}_joint</jointName>
                </plugin>
            </gazebo> -->
  <!-- <gazebo>
              <plugin name="f3d_${foot_prefix}_controller" filename="libgazebo_ros_f3d.so">
                <alwaysOn>true</alwaysOn>
                <updateRate>10.0</updateRate>
                <frameName>base_link</frameName>
                <bodyName>${foot_prefix}_Link</bodyName>
                <topicName>${foot_prefix}_force_ground_truth</topicName>
              </plugin>
            </gazebo> -->
  <gazebo reference="RH_FOOT_Link">
    <material>Gazebo/DarkGrey</material>
    <mu1 value="1000.0"/>
    <mu2 value="1000.0"/>
    <kp value="1000.0"/>
    <kd value="100.0"/>
    <fdir1 value="0 0 0"/>
    <minDepth value="0"/>
    <maxVel value="0"/>
  </gazebo>
  <gazebo reference="RH_FOOT_joint">
    <provideFeedback value="true"/>
  </gazebo>
  <gazebo reference="RH_FOOT_Link">
    <turnGravityOff>true</turnGravityOff>
    <selfCollide>false</selfCollide>
    <maxContacts>1</maxContacts>
    <sensor name="RH_FOOT_contact_sensor" type="contact">
      <update_rate>1000.0</update_rate>
      <contact>
        <collision>RH_ADAPTERLink_fixed_joint_lump__RH_FOOT_Link_collision_1</collision>
      </contact>
      <plugin filename="libgazebo_ros_bumper.so" name="RH_FOOT_gazebo_ros_bumper_controller">
        <alwaysOn>true</alwaysOn>
        <frameName>RH_FOOT_Link</frameName>
        <!-- <frameName>world</frameName> -->
        <updateRate>1000.0</updateRate>
        <bumperTopicName>RH_FOOT_bumper</bumperTopicName>
      </plugin>
    </sensor>
  </gazebo>
  <!-- <gazebo>
                <plugin name="ft_sensor" filename="libgazebo_ros_ft_sensor.so">
                    <updateRate>100.0</updateRate>
                    <topicName>${foot_prefix}_joint_ft_feedback</topicName>
                    <jointName>${foot_prefix}_joint</jointName>
                </plugin>
            </gazebo> -->
  <!-- <gazebo>
              <plugin name="f3d_${foot_prefix}_controller" filename="libgazebo_ros_f3d.so">
                <alwaysOn>true</alwaysOn>
                <updateRate>10.0</updateRate>
                <frameName>base_link</frameName>
                <bodyName>${foot_prefix}_Link</bodyName>
                <topicName>${foot_prefix}_force_ground_truth</topicName>
              </plugin>
            </gazebo> -->
  <gazebo reference="LH_FOOT_Link">
    <material>Gazebo/DarkGrey</material>
    <mu1 value="1000.0"/>
    <mu2 value="1000.0"/>
    <kp value="1000.0"/>
    <kd value="100.0"/>
    <fdir1 value="0 0 0"/>
    <minDepth value="0"/>
    <maxVel value="0"/>
  </gazebo>
  <gazebo reference="LH_FOOT_joint">
    <provideFeedback value="true"/>
  </gazebo>
  <gazebo reference="LH_FOOT_Link">
    <turnGravityOff>true</turnGravityOff>
    <selfCollide>false</selfCollide>
    <maxContacts>1</maxContacts>
    <sensor name="LH_FOOT_contact_sensor" type="contact">
      <update_rate>1000.0</update_rate>
      <contact>
        <collision>LH_ADAPTERLink_fixed_joint_lump__LH_FOOT_Link_collision_1</collision>
      </contact>
      <plugin filename="libgazebo_ros_bumper.so" name="LH_FOOT_gazebo_ros_bumper_controller">
        <alwaysOn>true</alwaysOn>
        <frameName>LH_FOOT_Link</frameName>
        <!-- <frameName>world</frameName> -->
        <updateRate>1000.0</updateRate>
        <bumperTopicName>LH_FOOT_bumper</bumperTopicName>
      </plugin>
    </sensor>
  </gazebo>
  <!-- <gazebo>
                <plugin name="ft_sensor" filename="libgazebo_ros_ft_sensor.so">
                    <updateRate>100.0</updateRate>
                    <topicName>${foot_prefix}_joint_ft_feedback</topicName>
                    <jointName>${foot_prefix}_joint</jointName>
                </plugin>
            </gazebo> -->
  <!-- <gazebo>
              <plugin name="f3d_${foot_prefix}_controller" filename="libgazebo_ros_f3d.so">
                <alwaysOn>true</alwaysOn>
                <updateRate>10.0</updateRate>
                <frameName>base_link</frameName>
                <bodyName>${foot_prefix}_Link</bodyName>
                <topicName>${foot_prefix}_force_ground_truth</topicName>
              </plugin>
            </gazebo> -->
  <link name="base">
    <visual>
      <origin rpy="0 0 0" xyz="0 0 0"/>
      <geometry>
        <box size="0.001 0.001 0.001"/>
      </geometry>
    </visual>
  </link>
  <joint name="floating_base" type="fixed">
    <origin rpy="0 0 0" xyz="0 0 0"/>
    <parent link="base"/>
    <child link="base_inertia"/>
  </joint>
  <link name="base_inertia">
    <inertial>
      <origin rpy="0 0 0" xyz="0.006699 -0.000736 0.001288"/>
      <mass value="27.801"/>
      <inertia ixx="0.263893" ixy="0" ixz="0" iyy="2.018032" iyz="0" izz="2.056458"/>
    </inertial>
    <visual>
      <origin rpy="0 0 0" xyz="0 0 0"/>
      <geometry>
        <mesh filename="package://simpledog_description/meshes/quadruped/untitled.dae"/>
      </geometry>
      <material name="">
        <color rgba="0.79216 0.81961 0.93333 1"/>
      </material>
    </visual>
    <collision>
      <origin rpy="0 0 0" xyz="0 0 0"/>
      <geometry>
        <mesh filename="package://simpledog_description/meshes/quadruped/untitled.dae"/>
      </geometry>
    </collision>
  </link>
  <link name="LF_HIP">
    <inertial>
      <origin rpy="0 0 0" xyz="0.000688 0.10488 -0.003776"/>
      <mass value="2.9231"/>
      <inertia ixx="0.004820" ixy="0" ixz="0" iyy="0.007868" iyz="0" izz="0.008241"/>
    </inertial>
    <visual>
      <origin rpy="0 0 0" xyz="0 0 0"/>
      <geometry>
        <mesh filename="package://simpledog_description/meshes/quadruped/Origin_front_left_1_link.STL"/>
      </geometry>
      <material name="">
        <color rgba="0.79216 0.81961 0.93333 1"/>
      </material>
    </visual>
    <collision>
      <origin rpy="0 0 0" xyz="0 0 0"/>
      <geometry>
        <mesh filename="package://simpledog_description/meshes/quadruped/Origin_front_left_1_link.STL"/>
      </geometry>
    </collision>
  </link>
  <joint name="LF_HAA" type="revolute">
    <origin rpy="0 1.5708 0" xyz="0.427 0.075 -0.0095"/>
    <parent link="base"/>
    <child link="LF_HIP"/>
    <axis xyz="0 0 1"/>
    <limit effort="300" lower="-3.0" upper="3.0" velocity="10"/>
  </joint>
  <link name="LF_THIGH">
    <inertial>
      <origin rpy="0 0 0" xyz="0.18475 3.2E-05 0.12906"/>
      <mass value="4.2164"/>
      <inertia ixx="0.006286" ixy="0" ixz="0" iyy="0.028156" iyz="0" izz="0.029242"/>
    </inertial>
    <visual>
      <origin rpy="0 0 0" xyz="0 0 0"/>
      <geometry>
        <mesh filename="package://simpledog_description/meshes/quadruped/Origin_front_left_2_link.STL"/>
      </geometry>
      <material name="">
        <color rgba="0.79216 0.81961 0.93333 1"/>
      </material>
    </visual>
    <collision>
      <origin rpy="0 0 0" xyz="0 0 0"/>
      <geometry>
        <mesh filename="package://simpledog_description/meshes/quadruped/Origin_front_left_2_link.STL"/>
      </geometry>
    </collision>
  </link>
  <joint name="LF_HFE" type="continuous">
    <origin rpy="-1.5708 0 0" xyz="0 0 0"/>
    <parent link="LF_HIP"/>
    <child link="LF_THIGH"/>
    <axis xyz="0 0 1"/>
    <limit effort="300" lower="-7.0" upper="7.0" velocity="10"/>
  </joint>
  <link name="LF_SHANK">
    <inertial>
      <origin rpy="0 0 0" xyz="0.20231 0.000199 0.22543"/>
      <mass value="0.44457"/>
      <inertia ixx="0.000385" ixy="0" ixz="0" iyy="0.006223" iyz="0" izz="0.006502"/>
    </inertial>
    <visual>
      <origin rpy="0 0 0" xyz="0 0 0"/>
      <geometry>
        <mesh filename="package://simpledog_description/meshes/quadruped/Origin_front_left_3_link.STL"/>
      </geometry>
      <material name="">
        <color rgba="0.79216 0.81961 0.93333 1"/>
      </material>
    </visual>
    <collision>
      <origin rpy="0 0 0" xyz="0 0 0"/>
      <geometry>
        <mesh filename="package://simpledog_description/meshes/quadruped/Origin_front_left_3_link.STL"/>
      </geometry>
    </collision>
  </link>
  <joint name="LF_KFE" type="continuous">
    <origin rpy="0 0 0" xyz="0.308 0 0"/>
    <parent link="LF_THIGH"/>
    <child link="LF_SHANK"/>
    <axis xyz="0 0 1"/>
    <limit effort="300" lower="-3.0" upper="3.0" velocity="10"/>
  </joint>
  <link name="LF_FOOT">
    <inertial>
      <origin rpy="0 0 0" xyz="0.022126 -1.2357E-13 0.00049896"/>
      <mass value="0.03332"/>
      <inertia ixx="0.000014" ixy="0" ixz="0" iyy="0.000014" iyz="0" izz="0.000019"/>
    </inertial>
    <visual>
      <origin rpy="0 0 0" xyz="0 0 0"/>
      <geometry>
        <mesh filename="package://simpledog_description/meshes/quadruped/Origin_lf_foot_link.STL"/>
      </geometry>
      <material name="">
        <color rgba="0 0 0 1"/>
      </material>
    </visual>
    <collision>
      <origin rpy="0 0 0" xyz="0 0 0"/>
      <geometry>
        <mesh filename="package://simpledog_description/meshes/quadruped/Origin_lf_foot_link.STL"/>
      </geometry>
    </collision>
  </link>
  <joint name="LF_ADAPTER" type="fixed">
    <origin rpy="0 0 0" xyz="0.308 0 0.23"/>
    <parent link="LF_SHANK"/>
    <child link="LF_FOOT"/>
    <axis xyz="0 0 0"/>
  </joint>
  <link name="RF_HIP">
    <inertial>
      <origin rpy="0 0 0" xyz="-0.000688 0.104882 0.003776"/>
      <mass value="2.923111"/>
      <inertia ixx="0.004820" ixy="0" ixz="0" iyy="0.007868" iyz="0" izz="0.008241"/>
    </inertial>
    <visual>
      <origin rpy="0 0 0" xyz="0 0 0"/>
      <geometry>
        <mesh filename="package://simpledog_description/meshes/quadruped/Origin_front_right_1_link.STL"/>
      </geometry>
      <material name="">
        <color rgba="0.79216 0.81961 0.93333 1"/>
      </material>
    </visual>
    <collision>
      <origin rpy="0 0 0" xyz="0 0 0"/>
      <geometry>
        <mesh filename="package://simpledog_description/meshes/quadruped/Origin_front_right_1_link.STL"/>
      </geometry>
    </collision>
  </link>
  <joint name="RF_HAA" type="revolute">
    <origin rpy="3.1416 1.5708 0" xyz="0.427 -0.075 -0.0095"/>
    <parent link="base"/>
    <child link="RF_HIP"/>
    <axis xyz="0 0 1"/>
    <limit effort="300" lower="-3.0" upper="3.0" velocity="10"/>
  </joint>
  <link name="RF_THIGH">
    <inertial>
      <origin rpy="0 0 0" xyz="0.184747 3.2E-05 0.129056"/>
      <mass value="4.216358"/>
      <inertia ixx="0.006286" ixy="0" ixz="0" iyy="0.028156" iyz="0" izz="0.029242"/>
    </inertial>
    <visual>
      <origin rpy="0 0 0" xyz="0 0 0"/>
      <geometry>
        <mesh filename="package://simpledog_description/meshes/quadruped/Origin_front_right_2_link.STL"/>
      </geometry>
      <material name="">
        <color rgba="0.79216 0.81961 0.93333 1"/>
      </material>
    </visual>
    <collision>
      <origin rpy="0 0 0" xyz="0 0 0"/>
      <geometry>
        <mesh filename="package://simpledog_description/meshes/quadruped/Origin_front_right_2_link.STL"/>
      </geometry>
    </collision>
  </link>
  <joint name="RF_HFE" type="continuous">
    <origin rpy="-1.5708 0 0" xyz="0 0 0"/>
    <parent link="RF_HIP"/>
    <child link="RF_THIGH"/>
    <axis xyz="0 0 1"/>
    <limit effort="300" lower="-7.0" upper="7.0" velocity="10"/>
  </joint>
  <link name="RF_SHANK">
    <inertial>
      <origin rpy="0 0 0" xyz="0.202313 0.000199 0.225432"/>
      <mass value="0.444569"/>
      <inertia ixx="0.000385" ixy="0" ixz="0" iyy="0.006223" iyz="0" izz="0.006502"/>
    </inertial>
    <visual>
      <origin rpy="0 0 0" xyz="0 0 0"/>
      <geometry>
        <mesh filename="package://simpledog_description/meshes/quadruped/Origin_front_right_3_link.STL"/>
      </geometry>
      <material name="">
        <color rgba="0.79216 0.81961 0.93333 1"/>
      </material>
    </visual>
    <collision>
      <origin rpy="0 0 0" xyz="0 0 0"/>
      <geometry>
        <mesh filename="package://simpledog_description/meshes/quadruped/Origin_front_right_3_link.STL"/>
      </geometry>
    </collision>
  </link>
  <joint name="RF_KFE" type="continuous">
    <origin rpy="0 0 0" xyz="0.308 0 0"/>
    <parent link="RF_THIGH"/>
    <child link="RF_SHANK"/>
    <axis xyz="0 0 1"/>
    <limit effort="300" lower="-3.0" upper="3.0" velocity="10"/>
  </joint>
  <link name="RF_FOOT">
    <inertial>
      <origin rpy="0 0 0" xyz="0.022126 -4.4892E-13 -1.0375E-06"/>
      <mass value="0.03332"/>
      <inertia ixx="0.000014" ixy="0" ixz="0" iyy="0.000014" iyz="0" izz="0.000019"/>
    </inertial>
    <visual>
      <origin rpy="0 0 0" xyz="0 0 0"/>
      <geometry>
        <mesh filename="package://simpledog_description/meshes/quadruped/Orgin_rf_foot_link.STL"/>
      </geometry>
      <material name="">
        <color rgba="0 0 0 1"/>
      </material>
    </visual>
    <collision>
      <origin rpy="0 0 0" xyz="0 0 0"/>
      <geometry>
        <mesh filename="package://simpledog_description/meshes/quadruped/Orgin_rf_foot_link.STL"/>
      </geometry>
    </collision>
  </link>
  <joint name="RF_ADAPTER" type="fixed">
    <origin rpy="0 0 0" xyz="0.308 0 0.22053"/>
    <parent link="RF_SHANK"/>
    <child link="RF_FOOT"/>
    <axis xyz="0 0 0"/>
  </joint>
  <link name="RH_HIP">
    <inertial>
      <origin rpy="0 0 0" xyz="0.000688 0.104882 0.003776"/>
      <mass value="2.923111"/>
      <inertia ixx="0.004820" ixy="0" ixz="0" iyy="0.007868" iyz="0" izz="0.008241"/>
    </inertial>
    <visual>
      <origin rpy="0 0 0" xyz="0 0 0"/>
      <geometry>
        <mesh filename="package://simpledog_description/meshes/quadruped/Origin_rear_right_1_link.STL"/>
      </geometry>
      <material name="">
        <color rgba="0.79216 0.81961 0.93333 1"/>
      </material>
    </visual>
    <collision>
      <origin rpy="0 0 0" xyz="0 0 0"/>
      <geometry>
        <mesh filename="package://simpledog_description/meshes/quadruped/Origin_rear_right_1_link.STL"/>
      </geometry>
    </collision>
  </link>
  <joint name="RH_HAA" type="revolute">
    <origin rpy="3.1416 1.5708 0" xyz="-0.427 -0.075 -0.0095"/>
    <parent link="base"/>
    <child link="RH_HIP"/>
    <axis xyz="0 0 1"/>
    <limit effort="300" lower="-3.0" upper="3.0" velocity="10"/>
  </joint>
  <link name="RH_THIGH">
    <inertial>
      <origin rpy="0 0 0" xyz="0.184747 3.2E-05 0.129056"/>
      <mass value="4.216358"/>
      <inertia ixx="0.006286" ixy="0" ixz="0" iyy="0.028156" iyz="0" izz="0.029242"/>
    </inertial>
    <visual>
      <origin rpy="0 0 0" xyz="0 0 0"/>
      <geometry>
        <mesh filename="package://simpledog_description/meshes/quadruped/Origin_rear_right_2_link.STL"/>
      </geometry>
      <material name="">
        <color rgba="0.79216 0.81961 0.93333 1"/>
      </material>
    </visual>
    <collision>
      <origin rpy="0 0 0" xyz="0 0 0"/>
      <geometry>
        <mesh filename="package://simpledog_description/meshes/quadruped/Origin_rear_right_2_link.STL"/>
      </geometry>
    </collision>
  </link>
  <joint name="RH_HFE" type="continuous">
    <origin rpy="-1.5708 0 0" xyz="0 0 0"/>
    <parent link="RH_HIP"/>
    <child link="RH_THIGH"/>
    <axis xyz="0 0 1"/>
    <limit effort="300" lower="-7.0" upper="7.0" velocity="10"/>
  </joint>
  <link name="RH_SHANK">
    <inertial>
      <origin rpy="0 0 0" xyz="0.202313 0.000199 0.225432"/>
      <mass value="0.444569"/>
      <inertia ixx="0.000385" ixy="0" ixz="0" iyy="0.006223" iyz="0" izz="0.006502"/>
    </inertial>
    <visual>
      <origin rpy="0 0 0" xyz="0 0 0"/>
      <geometry>
        <mesh filename="package://simpledog_description/meshes/quadruped/Origin_rear_right_3_link.STL"/>
      </geometry>
      <material name="">
        <color rgba="0.79216 0.81961 0.93333 1"/>
      </material>
    </visual>
    <collision>
      <origin rpy="0 0 0" xyz="0 0 0"/>
      <geometry>
        <mesh filename="package://simpledog_description/meshes/quadruped/Origin_rear_right_3_link.STL"/>
      </geometry>
    </collision>
  </link>
  <joint name="RH_KFE" type="continuous">
    <origin rpy="0 0 0" xyz="0.308 0 0"/>
    <parent link="RH_THIGH"/>
    <child link="RH_SHANK"/>
    <axis xyz="0 0 1"/>
    <limit effort="300" lower="-3.0" upper="3.0" velocity="10"/>
  </joint>
  <link name="RH_FOOT">
    <inertial>
      <origin rpy="0 0 0" xyz="0.022126 -1.6187E-13 -1E-06"/>
      <mass value="0.03332"/>
      <inertia ixx="0.000014" ixy="0" ixz="0" iyy="0.000014" iyz="0" izz="0.000019"/>
    </inertial>
    <visual>
      <origin rpy="0 0 0" xyz="0 0 0"/>
      <geometry>
        <mesh filename="package://simpledog_description/meshes/quadruped/Origin_rr_foot_link.STL"/>
      </geometry>
      <material name="">
        <color rgba="0 0 0 1"/>
      </material>
    </visual>
    <collision>
      <origin rpy="0 0 0" xyz="0 0 0"/>
      <geometry>
        <mesh filename="package://simpledog_description/meshes/quadruped/Origin_rr_foot_link.STL"/>
      </geometry>
    </collision>
  </link>
  <joint name="RH_ADAPTER" type="fixed">
    <origin rpy="0 0 0" xyz="0.308 0 0.22053"/>
    <parent link="RH_SHANK"/>
    <child link="RH_FOOT"/>
    <axis xyz="0 0 0"/>
  </joint>
  <link name="LH_HIP">
    <inertial>
      <origin rpy="0 0 0" xyz="-0.000688 0.10488 0.003776"/>
      <mass value="2.9231"/>
      <inertia ixx="0.004820" ixy="0" ixz="0" iyy="0.007868" iyz="0" izz="0.008241"/>
    </inertial>
    <visual>
      <origin rpy="0 0 0" xyz="0 0 0"/>
      <geometry>
        <mesh filename="package://simpledog_description/meshes/quadruped/Origin_rear_left_1_link.STL"/>
      </geometry>
      <material name="">
        <color rgba="0.79216 0.81961 0.93333 1"/>
      </material>
    </visual>
    <collision>
      <origin rpy="0 0 0" xyz="0 0 0"/>
      <geometry>
        <mesh filename="package://simpledog_description/meshes/quadruped/Origin_rear_left_1_link.STL"/>
      </geometry>
    </collision>
  </link>
  <joint name="LH_HAA" type="revolute">
    <origin rpy="0 1.5708 0" xyz="-0.427 0.075 -0.0095"/>
    <parent link="base"/>
    <child link="LH_HIP"/>
    <axis xyz="0 0 1"/>
    <limit effort="300" lower="-3.0" upper="3.0" velocity="10"/>
  </joint>
  <link name="LH_THIGH">
    <inertial>
      <origin rpy="0 0 0" xyz="0.184717 3.2E-05 0.129056"/>
      <mass value="4.216358"/>
      <inertia ixx="0.006286" ixy="0" ixz="0" iyy="0.028156" iyz="0" izz="0.029242"/>
    </inertial>
    <visual>
      <origin rpy="0 0 0" xyz="0 0 0"/>
      <geometry>
        <mesh filename="package://simpledog_description/meshes/quadruped/Origin_rear_left_2_link.STL"/>
      </geometry>
      <material name="">
        <color rgba="0.79216 0.81961 0.93333 1"/>
      </material>
    </visual>
    <collision>
      <origin rpy="0 0 0" xyz="0 0 0"/>
      <geometry>
        <mesh filename="package://simpledog_description/meshes/quadruped/Origin_rear_left_2_link.STL"/>
      </geometry>
    </collision>
  </link>
  <joint name="LH_HFE" type="continuous">
    <origin rpy="-1.5708 0 0" xyz="0 0 0"/>
    <parent link="LH_HIP"/>
    <child link="LH_THIGH"/>
    <axis xyz="0 0 1"/>
    <limit effort="300" lower="-7.0" upper="7.0" velocity="10"/>
  </joint>
  <link name="LH_SHANK">
    <inertial>
      <origin rpy="0 0 0" xyz="0.202313 0.000199 0.225432"/>
      <mass value="0.444569"/>
      <inertia ixx="0.000385" ixy="0" ixz="0" iyy="0.006223" iyz="0" izz="0.006502"/>
    </inertial>
    <visual>
      <origin rpy="0 0 0" xyz="0 0 0"/>
      <geometry>
        <mesh filename="package://simpledog_description/meshes/quadruped/Origin_rear_left_3_link.STL"/>
      </geometry>
      <material name="">
        <color rgba="0.79216 0.81961 0.93333 1"/>
      </material>
    </visual>
    <collision>
      <origin rpy="0 0 0" xyz="0 0 0"/>
      <geometry>
        <mesh filename="package://simpledog_description/meshes/quadruped/Origin_rear_left_3_link.STL"/>
      </geometry>
    </collision>
  </link>
  <joint name="LH_KFE" type="continuous">
    <origin rpy="0 0 0" xyz="0.308 0 0"/>
    <parent link="LH_THIGH"/>
    <child link="LH_SHANK"/>
    <axis xyz="0 0 1"/>
    <limit effort="300" lower="-3.0" upper="3.0" velocity="10"/>
  </joint>
  <link name="LH_FOOT">
    <inertial>
      <origin rpy="0 0 0" xyz="0.022126 -7.7827E-14 0.00049896"/>
      <mass value="0.03332"/>
      <inertia ixx="0.000014" ixy="0" ixz="0" iyy="0.000014" iyz="0" izz="0.000019"/>
    </inertial>
    <visual>
      <origin rpy="0 0 0" xyz="0 0 0"/>
      <geometry>
        <mesh filename="package://simpledog_description/meshes/quadruped/Origin_rl_foot_link.STL"/>
      </geometry>
      <material name="">
        <color rgba="0 0 0 1"/>
      </material>
    </visual>
    <collision>
      <origin rpy="0 0 0" xyz="0 0 0"/>
      <geometry>
        <mesh filename="package://simpledog_description/meshes/quadruped/Origin_rl_foot_link.STL"/>
      </geometry>
    </collision>
  </link>
  <joint name="LH_ADAPTER" type="fixed">
    <origin rpy="0 0 0" xyz="0.308 0 0.23"/>
    <parent link="LH_SHANK"/>
    <child link="LH_FOOT"/>
    <axis xyz="0 0 0"/>
  </joint>
  <!--  <link
    name="base_wheel">
    <inertial>
      <origin
        xyz="0 0 0"
        rpy="0 0 0" />
      <mass
        value="0.12006" />
      <inertia
        ixx="2.6585E-05"
        ixy="2.7219E-21"
        ixz="-3.7146E-22"
        iyy="1.0699E-05"
        iyz="-1.8974E-22"
        izz="3.5324E-05" />
    </inertial>
    <visual>
      <origin
        xyz="0 0 0"
        rpy="0 0 0" />
      <geometry>
        <mesh
          filename="package://simpledog_description/meshes/chassis.dae" />
      </geometry>
      <material
        name="">
        <color
          rgba="0.52941 0.54902 0.54902 1" />
      </material>
    </visual>
    <collision>
      <origin
        xyz="0 0 0"
        rpy="0 0 0" />
      <geometry>
        <mesh
          filename="package://simpledog_description/meshes/chassis.dae" />
      </geometry>
    </collision>
  </link>
    <joint
    name="base_wheel_joint"
    type="fixed">
    <origin
      xyz="0 0 -0.08"
      rpy="0 0 0" />
    <parent
      link="base" />
    <child
      link="base_wheel" />
    <axis
      xyz="0 0 0" />
  </joint>
  <link
    name="left_wheel">
    <inertial>
      <origin
        xyz="0 0 0"
        rpy="0 0 0" />
      <mass
        value="3.02006" />
      <inertia
        ixx="2.6585E-05"
        ixy="2.7219E-21"
        ixz="-3.7146E-22"
        iyy="1.0699E-05"
        iyz="-1.8974E-22"
        izz="3.5324E-05" />
    </inertial>
    <visual>
      <origin
        xyz="0 0 0"
        rpy="0 0 0" />
      <geometry>
        <mesh
          filename="package://simpledog_description/meshes/wheel.dae" />
      </geometry>
      <material
        name="">
        <color
          rgba="0.52941 0.54902 0.54902 1" />
      </material>
    </visual>
    <collision>
      <origin
        xyz="0 0 0"
        rpy="0 0 0" />
      <geometry>
        <mesh
          filename="package://simpledog_description/meshes/wheel.dae" />
      </geometry>
    </collision>
  </link>
    <joint
    name="left_wheel_joint"
    type="continuous">
    <origin
      xyz="0 0.18 -0.1"
      rpy="0 0 0" />
    <parent
      link="base_wheel" />
    <child
      link="left_wheel" />
    <axis
      xyz="0 1 0" />
  </joint>
  <link
    name="right_wheel">
    <inertial>
      <origin
        xyz="0 0 0"
        rpy="0 0 0" />
      <mass
        value="3.02006" />
      <inertia
        ixx="2.6585E-05"
        ixy="2.7219E-21"
        ixz="-3.7146E-22"
        iyy="1.0699E-05"
        iyz="-1.8974E-22"
        izz="3.5324E-05" />
    </inertial>
    <visual>
      <origin
        xyz="0 0 0"
        rpy="0 0 0" />
      <geometry>
        <mesh
          filename="package://simpledog_description/meshes/wheel.dae" />
      </geometry>
      <material
        name="">
        <color
          rgba="0.52941 0.54902 0.54902 1" />
      </material>
    </visual>
    <collision>
      <origin
        xyz="0 0 0"
        rpy="0 0 0" />
      <geometry>
        <mesh
          filename="package://simpledog_description/meshes/wheel.dae" />
      </geometry>
    </collision>
  </link>
    <joint
    name="right_wheel_joint"
    type="continuous">
    <origin
      xyz="0 -0.18 -0.1"
      rpy="0 0 0" />
    <parent
      link="base_wheel" />
    <child
      link="right_wheel" />
    <axis
      xyz="0 1 0" />
  </joint>
  <link
    name="front_wheel">
    <inertial>
      <origin

        xyz="0 0 0"
        rpy="0 0 0" />
      <mass
        value="2.02006" />
      <inertia
        ixx="2.6585E-05"
        ixy="2.7219E-21"
        ixz="-3.7146E-22"
        iyy="1.0699E-05"
        iyz="-1.8974E-22"
        izz="3.5324E-05" />
    </inertial>
    <visual>
      <origin
        xyz="0 0 0"
        rpy="0 0 0" />
      <geometry>
        <sphere radius="0.06"/>
      </geometry>
      <material
        name="">
        <color
          rgba="0.52941 0.54902 0.54902 1" />
      </material>
    </visual>
    <collision>
      <origin
        xyz="0 0 0"
        rpy="0 0 0" />
      <geometry>
          <sphere radius="0.06"/>
      </geometry>
    </collision>
  </link>
    <joint
    name="front_wheel_joint"
    type="continuous">
    <origin
      xyz="0.2 0 -0.15"
      rpy="0 0 0" />
    <parent

      link="base_wheel" />
    <child
      link="front_wheel" />
    <axis
      xyz="0 1 1" />
  </joint>
  <link
    name="rear_wheel">
    <inertial>
      <origin
        xyz="0 0 0"
        rpy="0 0 0" />
      <mass
        value="2.02006" />
      <inertia
        ixx="2.6585E-05"
        ixy="2.7219E-21"
        ixz="-3.7146E-22"
        iyy="1.0699E-05"
        iyz="-1.8974E-22"
        izz="3.5324E-05" />
    </inertial>
    <visual>
      <origin
        xyz="0 0 0"
        rpy="0 0 0" />
      <geometry>
        <sphere radius="0.06"/>
      </geometry>
      <material
        name="">
        <color
          rgba="0.52941 0.54902 0.54902 1" />
      </material>
    </visual>
    <collision>
      <origin
        xyz="0 0 0"
        rpy="0 0 0" />
      <geometry>
          <sphere radius="0.06"/>
      </geometry>
    </collision>
  </link>
    <joint
    name="rear_wheel_joint"
    type="continuous">
    <origin
      xyz="-0.2 0 -0.15"
      rpy="0 0 0" />
    <parent
      link="base_wheel" />
    <child
      link="rear_wheel" />
    <axis
      xyz="0 1 1" />
  </joint>
  <transmission name="RF_joint_trans">
      <type>transmission_interface/SimpleTransmission</type>
      <joint name="right_wheel_joint" />
      <actuator name="RF_joint_motor">
          <hardwareInterface>VelocityJointInterface</hardwareInterface>
          <mechanicalReduction>1</mechanicalReduction>
      </actuator>
  </transmission>
  <transmission name="LF_joint_trans">
      <type>transmission_interface/SimpleTransmission</type>
      <joint name="left_wheel_joint" />
      <actuator name="LF_joint_motor">
          <hardwareInterface>VelocityJointInterface</hardwareInterface>
          <mechanicalReduction>1</mechanicalReduction>
      </actuator>
  </transmission>
  <gazebo>
    <plugin name="differential_drive_controller" filename="libgazebo_ros_diff_drive.so">
        <alwaysOn>true</alwaysOn>
        <updateRate>50.0</updateRate>
        <leftJoint>left_wheel_joint</leftJoint>
        <rightJoint>right_wheel_joint</rightJoint>
        <wheelSeparation>0.36</wheelSeparation>
        <wheelDiameter>0.22</wheelDiameter>
        <torque>50.0</torque>
        <commandTopic>wheel_cmd_vel</commandTopic>
        <odometryTopic>wheel_odom</odometryTopic>
        <odometryFrame>wheel_odom</odometryFrame>
        <robotBaseFrame>base</robotBaseFrame>
        <publishWheelTF>false</publishWheelTF>
        <publishWheelJointState>false</publishWheelJointState>
        <legecyMode>false</legecyMode>
        <wheelAcceleration>1</wheelAcceleration>
    </plugin>
  </gazebo>
          <gazebo reference="right_wheel">
              <mu1 value="10.0"/>
              <mu2 value="10.0"/>
          </gazebo>
          <gazebo reference="left_wheel">
              <mu1 value="10.0"/>
              <mu2 value="10.0"/>
          </gazebo> -->
</robot>

